<?xml version='1.0'?>
<sdf version='1.4'>
  <model name="arm">
  <static>false</static>
  <link name="chassis">
    <pose>0 0 .05 0 0 0</pose>
       <mass>50</mass>
    <collision name='collision'>
            <geometry>
                <cylinder>
                  <radius>0.5</radius>
                  <length>0.1</length>
                </cylinder>
              </geometry>
            </collision>
            <visual name='visual'>        
              <geometry>
                <cylinder>
                  <radius>0.5</radius>
                  <length>0.1</length>
                </cylinder>
              </geometry>
            </visual>  
    </link>
    <link name="arm1">
    <gravity>0</gravity>
    <pose>0 0 0.125 0 0 0</pose>
     <collision name='collision'>
            <geometry>
                <cylinder>
                  <radius>0.1</radius>
                  <length>0.05</length>
                </cylinder>
              </geometry>
            </collision>
            <visual name='visual'>        
              <geometry>
                <cylinder>
                  <radius>0.1</radius>
                  <length>0.05</length>
                </cylinder>
              </geometry>
            </visual> 
    
    </link>
    <link name="arm2">
    <gravity>0</gravity>
    <pose>0 0 1.15 0 0 0</pose>
     <collision name='collision'>
            <geometry>
                <cylinder>
                  <radius>0.05</radius>
                  <length>2.0</length>
                </cylinder>
              </geometry>
            </collision>
            <visual name='visual'>        
              <geometry>
                <cylinder>
                  <radius>0.05</radius>
                  <length>2.0</length>
                </cylinder>
              </geometry>
            </visual> 
    
    </link>
    <link name="arm3">
    <gravity>0</gravity>
    <pose>0 0 2.65 0 0 0</pose>
     <collision name='collision'>
            <geometry>
                <cylinder>
                  <radius>0.05</radius>
                  <length>1.0</length>
                </cylinder>
              </geometry>
            </collision>
            <visual name='visual'>        
              <geometry>
                <cylinder>
                  <radius>0.05</radius>
                  <length>1.0</length>
                </cylinder>
              </geometry>
            </visual> 
    
    </link>
    <link name="arm4">
    <gravity>0</gravity>
    <pose>0 0 3.4 0 0 0</pose>
     <collision name='collision'>
            <geometry>
                <cylinder>
                  <radius>0.05</radius>
                  <length>0.5</length>
                </cylinder>
              </geometry>
            </collision>
            <visual name='visual'>        
              <geometry>
                <cylinder>
                  <radius>0.05</radius>
                  <length>0.5</length>
                </cylinder>
              </geometry>
            </visual> 
    
    </link>
     <link name="gripper">
    <gravity>0</gravity>
    <pose>0 0 3.7 0 0 0</pose>
     <collision name='collision'>
            <geometry>
                <sphere>
                  <radius>0.05</radius>
                </sphere>
              </geometry>
            </collision>
            <visual name='visual'>        
              <geometry>
                <sphere>
                  <radius>0.05</radius>
                </sphere>
              </geometry>
            </visual> 
    
    </link>
     <link name="palm">
      <!-- <gravity>0</gravity> -->
            <pose>0.0 0.0 3.75 0 0 0</pose>
            <inertial>
               
                <mass>0.5</mass>
            </inertial>
            <collision name="collision">
                <geometry>
                    <box>
                        <size>0.1 0.3 0.1</size>
                    </box>
                </geometry>
            </collision>
            <visual name="visual">
                <geometry>
                    <box>
                        <size>0.1 0.3 0.1</size>
                    </box>
                </geometry>
                <material>
                    <script>Gazebo/Red</script>
                </material>
            </visual>
        </link>
        <link name="left_finger">
        <!-- <gravity>0</gravity> -->
            <pose>0.1 0.2 3.75 0 0 -0.78539</pose>
            <inertial>
               
                <mass>0.1</mass>
            </inertial>
            <collision name="collision">
                <geometry>
                    <box>
                        <size>0.1 0.3 0.1</size>
                    </box>
                </geometry>
            </collision>
            <visual name="visual">
                <geometry>
                    <box>
                        <size>0.1 0.3 0.1</size>
                    </box>
                </geometry>
                <material>
                    <script>Gazebo/Blue</script>
                </material>
            </visual>
        </link>
        <link name="right_finger">
        <!-- <gravity>0</gravity> -->
            <pose>0.1 -0.2 3.75 0 0 .78539</pose>
            <inertial>
                
                <mass>0.1</mass>
            </inertial>
            <collision name="collision">
                <geometry>
                    <box>
                        <size>0.1 0.3 0.1</size>
                    </box>
                </geometry>
            </collision>
            <visual name="visual">
                <geometry>
                    <box>
                        <size>0.1 0.3 0.1</size>
                    </box>
                </geometry>
                <material>
                    <script>Gazebo/Green</script>
                </material>
            </visual>
        </link> -->
    <joint name="chassis_arm1_joint" type="revolute">
       <parent>chassis</parent>
       <child>arm1</child>
       <pose>0 0 -0.025 0 0</pose>
       <axis>
          <xyz> 0 0 1</xyz>
       </axis>
    </joint>
    <joint name="arm1_arm2_joint" type="revolute">
       <parent>arm1</parent>
       <child>arm2</child>
       <pose>0 0 -1 0 0 0</pose>
       <axis>
          <xyz> 1 0 0</xyz>
       </axis>
       <!-- <dynamic>
            <damping>5</damping>
            <friction>5</friction>
       </dynamic>
       <limit>
            <lower>-1</lower>
            <upper>1</upper>
            <velocity>-1</velocity>
            <effort>-1</effort>
       </limit> -->
    </joint>
    <joint name="arm2_arm3_joint" type="revolute">
       <parent>arm2</parent>
       <child>arm3</child>
       <pose>0 0 -0.5 0 0 0</pose>
       <axis>
          <xyz> 1 0 0</xyz>
       </axis>
    </joint>
    <joint name="arm3_arm4_joint" type="revolute">
       <parent>arm3</parent>
       <child>arm4</child>
       <pose>0 0 -0.25 0 0 0</pose>
       <axis>
          <xyz> 1 0 0</xyz>
       </axis>
       <!-- <dynamic>
            <damping>5</damping>
            <friction>5</friction>
       </dynamic>
       <limit>
            <lower>-1</lower>
            <upper>1</upper>
            <velocity>-1</velocity>
            <effort>-1</effort>
       </limit> -->
    </joint>
     <joint name="arm4_gripper_joint" type="revolute">
       <parent>arm4</parent>
       <child>gripper</child>
       <pose>0 0 -0.05 0 0 0</pose>
       <axis>
          <xyz> 1 0 0</xyz>
       </axis>
    </joint>
     <joint name="gripper_palm_joint" type="revolute">
       <parent>gripper</parent>
       <child>palm</child>
       <pose>0 0 -0.1 0 0 0</pose>
       <axis>
          <xyz> 1 0 0</xyz>
       </axis>
    </joint>
     <joint name="palm_left_finger" type="revolute">
            <pose>0 -0.15 0 0 0 0</pose>
            <child>left_finger</child>
            <parent>palm</parent>
            <axis>
                <limit>
                    <lower>-0.4</lower>
                    <upper>0.4</upper>
                </limit>
                <xyz>0 0 1</xyz>
            </axis>
            </joint>
      <joint name="palm_right_finger" type="revolute">
            <pose>0 0.15 0 0 0 0</pose>
            <child>right_finger</child>
            <parent>palm</parent>
            <axis>
                <limit>
                    <lower>-0.4</lower>
                    <upper>0.4</upper>
                </limit>
                <xyz>0 0 1</xyz>
            </axis>
        </joint>
   <plugin name="arm_control" filename="libarm_gazebo.so" />
  </model>
</sdf>

    